<?xml version="1.0" encoding="utf-8"?>
<!-- This URDF was automatically created by SolidWorks to URDF Exporter! Originally created by Stephen Brawner (brawner@gmail.com) 
     Commit Version: 1.6.0-4-g7f85cfe  Build Version: 1.6.7995.38578
     For more information, please see http://wiki.ros.org/sw_urdf_exporter -->
<robot
  name="mobiman/urdf/R1">
  <link
    name="base_link">
    <inertial>
      <origin
        xyz="0.00067851 4.1152E-07 0.12993"
        rpy="0 0 0" />
      <mass
        value="28.1" />
      <inertia
        ixx="0.41116"
        ixy="6.0087E-08"
        ixz="0.00057578"
        iyy="0.27395"
        iyz="-7.2731E-08"
        izz="0.50093" />
    </inertial>
    <visual>
      <origin
        xyz="0 0 0"
        rpy="0 0 0" />
      <geometry>
        <mesh
          filename="package://mobiman/urdf/R1/meshes/base_link.STL" />
      </geometry>
      <material
        name="">
        <color
          rgba="0.59608 0.66667 0.68627 1" />
      </material>
    </visual>
    <collision>
      <origin
        xyz="0 0 0"
        rpy="0 0 0" />
      <geometry>
        <mesh
          filename="package://mobiman/urdf/R1/meshes/base_link.STL" />
      </geometry>
    </collision>
  </link>
  <link
    name="servo_link1">
    <inertial>
      <origin
        xyz="-0.00031065 -0.022512 -0.030846"
        rpy="0 0 0" />
      <mass
        value="1" />
      <inertia
        ixx="0.00022554"
        ixy="2.4928E-06"
        ixz="8.1645E-07"
        iyy="0.00016547"
        iyz="-6.6947E-05"
        izz="0.00014555" />
    </inertial>
    <visual>
      <origin
        xyz="0 0 0"
        rpy="0 0 0" />
      <geometry>
        <mesh
          filename="package://mobiman/urdf/R1/meshes/servo_link1.STL" />
      </geometry>
      <material
        name="">
        <color
          rgba="0.69412 0.69412 0.69412 1" />
      </material>
    </visual>
    <collision>
      <origin
        xyz="0 0 0"
        rpy="0 0 0" />
      <geometry>
        <mesh
          filename="package://mobiman/urdf/R1/meshes/servo_link1.STL" />
      </geometry>
    </collision>
  </link>
  <joint
    name="servo_axis1"
    type="revolute">
    <origin
      xyz="0.15169 0.185 0.121"
      rpy="0 0 0" />
    <parent
      link="base_link" />
    <child
      link="servo_link1" />
    <axis
      xyz="0 0 1" />
    <limit
      lower="-1.6581"
      upper="1.6581"
      effort="44"
      velocity="3.1416" />
  </joint>
  <link
    name="wheel_link1">
    <inertial>
      <origin
        xyz="6.5501E-08 4.1927E-07 -0.032644"
        rpy="0 0 0" />
      <mass
        value="2.2" />
      <inertia
        ixx="0.0008746"
        ixy="-5.1589E-11"
        ixz="-6.3041E-10"
        iyy="0.00087462"
        iyz="5.5928E-10"
        izz="0.0014051" />
    </inertial>
    <visual>
      <origin
        xyz="0 0 0"
        rpy="0 0 0" />
      <geometry>
        <mesh
          filename="package://mobiman/urdf/R1/meshes/wheel_link1.STL" />
      </geometry>
      <material
        name="">
        <color
          rgba="0.79216 0.81961 0.93333 1" />
      </material>
    </visual>
    <collision>
      <origin
        xyz="0 0 0"
        rpy="0 0 0" />
      <geometry>
        <mesh
          filename="package://mobiman/urdf/R1/meshes/wheel_link1.STL" />
      </geometry>
    </collision>
  </link>
  <joint
    name="wheel_axis1"
    type="continuous">
    <origin
      xyz="0 0.032 -0.0905"
      rpy="-1.5708 0 0" />
    <parent
      link="servo_link1" />
    <child
      link="wheel_link1" />
    <axis
      xyz="0 0 1" />
  </joint>
  <link
    name="servo_link2">
    <inertial>
      <origin
        xyz="0.00031065 0.022512 -0.030846"
        rpy="0 0 0" />
      <mass
        value="1" />
      <inertia
        ixx="0.00022554"
        ixy="2.4928E-06"
        ixz="-8.1645E-07"
        iyy="0.00016547"
        iyz="6.6947E-05"
        izz="0.00014555" />
    </inertial>
    <visual>
      <origin
        xyz="0 0 0"
        rpy="0 0 0" />
      <geometry>
        <mesh
          filename="package://mobiman/urdf/R1/meshes/servo_link2.STL" />
      </geometry>
      <material
        name="">
        <color
          rgba="0.69412 0.69412 0.69412 1" />
      </material>
    </visual>
    <collision>
      <origin
        xyz="0 0 0"
        rpy="0 0 0" />
      <geometry>
        <mesh
          filename="package://mobiman/urdf/R1/meshes/servo_link2.STL" />
      </geometry>
    </collision>
  </link>
  <joint
    name="servo_axis2"
    type="revolute">
    <origin
      xyz="0.15169 -0.185 0.121"
      rpy="0 0 0" />
    <parent
      link="base_link" />
    <child
      link="servo_link2" />
    <axis
      xyz="0 0 1" />
    <limit
      lower="-1.6581"
      upper="1.6581"
      effort="44"
      velocity="3.1416" />
  </joint>
  <link
    name="wheel_link2">
    <inertial>
      <origin
        xyz="-6.5501E-08 4.1927E-07 0.032644"
        rpy="0 0 0" />
      <mass
        value="2.2" />
      <inertia
        ixx="0.0008746"
        ixy="5.1589E-11"
        ixz="-6.3041E-10"
        iyy="0.00087462"
        iyz="-5.5928E-10"
        izz="0.0014051" />
    </inertial>
    <visual>
      <origin
        xyz="0 0 0"
        rpy="0 0 0" />
      <geometry>
        <mesh
          filename="package://mobiman/urdf/R1/meshes/wheel_link2.STL" />
      </geometry>
      <material
        name="">
        <color
          rgba="0.79216 0.81961 0.93333 1" />
      </material>
    </visual>
    <collision>
      <origin
        xyz="0 0 0"
        rpy="0 0 0" />
      <geometry>
        <mesh
          filename="package://mobiman/urdf/R1/meshes/wheel_link2.STL" />
      </geometry>
    </collision>
  </link>
  <joint
    name="wheel_axis2"
    type="continuous">
    <origin
      xyz="0 -0.032 -0.0905"
      rpy="-1.5708 0 0" />
    <parent
      link="servo_link2" />
    <child
      link="wheel_link2" />
    <axis
      xyz="0 0 1" />
  </joint>
  <link
    name="servo_link3">
    <inertial>
      <origin
        xyz="-0.00031065 -0.022512 -0.030846"
        rpy="0 0 0" />
      <mass
        value="1" />
      <inertia
        ixx="0.00022554"
        ixy="2.4928E-06"
        ixz="8.1645E-07"
        iyy="0.00016547"
        iyz="-6.6947E-05"
        izz="0.00014555" />
    </inertial>
    <visual>
      <origin
        xyz="0 0 0"
        rpy="0 0 0" />
      <geometry>
        <mesh
          filename="package://mobiman/urdf/R1/meshes/servo_link3.STL" />
      </geometry>
      <material
        name="">
        <color
          rgba="0.69412 0.69412 0.69412 1" />
      </material>
    </visual>
    <collision>
      <origin
        xyz="0 0 0"
        rpy="0 0 0" />
      <geometry>
        <mesh
          filename="package://mobiman/urdf/R1/meshes/servo_link3.STL" />
      </geometry>
    </collision>
  </link>
  <joint
    name="servo_axis3"
    type="revolute">
    <origin
      xyz="-0.15431 0 0.121"
      rpy="0 0 0" />
    <parent
      link="base_link" />
    <child
      link="servo_link3" />
    <axis
      xyz="0 0 1" />
    <limit
      lower="-1.6581"
      upper="1.6581"
      effort="44"
      velocity="3.1416" />
  </joint>
  <link
    name="wheel_link3">
    <inertial>
      <origin
        xyz="6.5501E-08 4.1927E-07 -0.032644"
        rpy="0 0 0" />
      <mass
        value="2.2" />
      <inertia
        ixx="0.0008746"
        ixy="-5.1589E-11"
        ixz="-6.3041E-10"
        iyy="0.00087462"
        iyz="5.5928E-10"
        izz="0.0014051" />
    </inertial>
    <visual>
      <origin
        xyz="0 0 0"
        rpy="0 0 0" />
      <geometry>
        <mesh
          filename="package://mobiman/urdf/R1/meshes/wheel_link3.STL" />
      </geometry>
      <material
        name="">
        <color
          rgba="0.79216 0.81961 0.93333 1" />
      </material>
    </visual>
    <collision>
      <origin
        xyz="0 0 0"
        rpy="0 0 0" />
      <geometry>
        <mesh
          filename="package://mobiman/urdf/R1/meshes/wheel_link3.STL" />
      </geometry>
    </collision>
  </link>
  <joint
    name="wheel_axis3"
    type="continuous">
    <origin
      xyz="0 0.032 -0.0905"
      rpy="-1.5708 0 0" />
    <parent
      link="servo_link3" />
    <child
      link="wheel_link3" />
    <axis
      xyz="0 0 1" />
  </joint>
  <link
    name="torso_link1">
    <inertial>
      <origin
        xyz="-4.6645E-05 -0.086098 -0.064"
        rpy="0 0 0" />
      <mass
        value="4.286" />
      <inertia
        ixx="0.030007"
        ixy="0.00026616"
        ixz="2.1339E-08"
        iyy="0.0035268"
        iyz="-2.2166E-08"
        izz="0.030358" />
    </inertial>
    <visual>
      <origin
        xyz="0 0 0"
        rpy="0 0 0" />
      <geometry>
        <mesh
          filename="package://mobiman/urdf/R1/meshes/torso_link1.STL" />
      </geometry>
      <material
        name="">
        <color
          rgba="0.82353 0.82353 1 1" />
      </material>
    </visual>
    <collision>
      <origin
        xyz="0 0 0"
        rpy="0 0 0" />
      <geometry>
        <mesh
          filename="package://mobiman/urdf/R1/meshes/torso_link1.STL" />
      </geometry>
    </collision>
  </link>
  <joint
    name="torso_joint1"
    type="revolute">
    <origin
      xyz="-0.05431 0.064001 0.26686"
      rpy="-1.5708 0 0" />
    <parent
      link="base_link" />
    <child
      link="torso_link1" />
    <axis
      xyz="0 0 1" />
    <limit
      lower="-1.0472"
      upper="2.1817"
      effort="100"
      velocity="2.0944" />
  </joint>
  <link
    name="torso_link2">
    <inertial>
      <origin
        xyz="0.0041875 -0.14057 -0.046768"
        rpy="0 0 0" />
      <mass
        value="5.153" />
      <inertia
        ixx="0.020253"
        ixy="-0.00016018"
        ixz="1.968E-06"
        iyy="0.001483"
        iyz="-1.5818E-06"
        izz="0.021666" />
    </inertial>
    <visual>
      <origin
        xyz="0 0 0"
        rpy="0 0 0" />
      <geometry>
        <mesh
          filename="package://mobiman/urdf/R1/meshes/torso_link2.STL" />
      </geometry>
      <material
        name="">
        <color
          rgba="0.82353 0.82353 1 1" />
      </material>
    </visual>
    <collision>
      <origin
        xyz="0 0 0"
        rpy="0 0 0" />
      <geometry>
        <mesh
          filename="package://mobiman/urdf/R1/meshes/torso_link2.STL" />
      </geometry>
    </collision>
  </link>
  <joint
    name="torso_joint2"
    type="revolute">
    <origin
      xyz="0 -0.40014 0"
      rpy="0 0 0" />
    <parent
      link="torso_link1" />
    <child
      link="torso_link2" />
    <axis
      xyz="0 0 1" />
    <limit
      lower="-2.618"
      upper="1.9199"
      effort="100"
      velocity="2.0944" />
  </joint>
  <link
    name="torso_link3">
    <inertial>
      <origin
        xyz="-2.0681E-07 0.015762 0.064"
        rpy="0 0 0" />
      <mass
        value="6.533" />
      <inertia
        ixx="0.0024012"
        ixy="1.7123E-08"
        ixz="-1.3876E-09"
        iyy="0.0014135"
        iyz="-7.5331E-09"
        izz="0.0028934" />
    </inertial>
    <visual>
      <origin
        xyz="0 0 0"
        rpy="0 0 0" />
      <geometry>
        <mesh
          filename="package://mobiman/urdf/R1/meshes/torso_link3.STL" />
      </geometry>
      <material
        name="">
        <color
          rgba="0.82353 0.82353 1 1" />
      </material>
    </visual>
    <collision>
      <origin
        xyz="0 0 0"
        rpy="0 0 0" />
      <geometry>
        <mesh
          filename="package://mobiman/urdf/R1/meshes/torso_link3.STL" />
      </geometry>
    </collision>
  </link>
  <joint
    name="torso_joint3"
    type="revolute">
    <origin
      xyz="0 -0.3 0"
      rpy="3.1416 0 0" />
    <parent
      link="torso_link2" />
    <child
      link="torso_link3" />
    <axis
      xyz="0 0 1" />
    <limit
      lower="-1.5708"
      upper="1.5708"
      effort="100"
      velocity="2.0944" />
  </joint>
  <link
    name="torso_link4">
    <inertial>
      <origin
        xyz="-0.0026333 -1.4443E-07 0.38669"
        rpy="0 0 0" />
      <mass
        value="16.778" />
      <inertia
        ixx="0.015271"
        ixy="4.4444E-08"
        ixz="0.00054617"
        iyy="0.013562"
        iyz="-2.0233E-07"
        izz="0.017441" />
    </inertial>
    <visual>
      <origin
        xyz="0 0 0"
        rpy="0 0 0" />
      <geometry>
        <mesh
          filename="package://mobiman/urdf/R1/meshes/torso_link4.STL" />
      </geometry>
      <material
        name="">
        <color
          rgba="0.81176 0.84314 0.9098 1" />
      </material>
    </visual>
    <collision>
      <origin
        xyz="0 0 0"
        rpy="0 0 0" />
      <geometry>
        <mesh
          filename="package://mobiman/urdf/R1/meshes/torso_link4.STL" />
      </geometry>
    </collision>
  </link>
  <joint
    name="torso_joint4"
    type="revolute">
    <origin
      xyz="0 0.0935 0.064"
      rpy="-1.5708 0 0" />
    <parent
      link="torso_link3" />
    <child
      link="torso_link4" />
    <axis
      xyz="0 0 1" />
    <limit
      lower="-2.9671"
      upper="2.9671"
      effort="100"
      velocity="2.0944" />
  </joint>
  <link
    name="left_arm_link1">
    <inertial>
      <origin
        xyz="0.025904 0.089421 0.19171"
        rpy="0 0 0" />
      <mass
        value="1.319" />
      <inertia
        ixx="0.00058101"
        ixy="7.5672E-09"
        ixz="2.9207E-08"
        iyy="0.00070857"
        iyz="8.5639E-07"
        izz="0.00044583" />
    </inertial>
    <visual>
      <origin
        xyz="0 0 0"
        rpy="0 0 0" />
      <geometry>
        <mesh
          filename="package://mobiman/urdf/R1/meshes/left_arm_link1.STL" />
      </geometry>
      <material
        name="">
        <color
          rgba="0.79216 0.81961 0.93333 1" />
      </material>
    </visual>
    <collision>
      <origin
        xyz="0 0 0"
        rpy="0 0 0" />
      <geometry>
        <mesh
          filename="package://mobiman/urdf/R1/meshes/left_arm_link1.STL" />
      </geometry>
    </collision>
  </link>
  <joint
    name="left_arm_joint1"
    type="revolute">
    <origin
      xyz="-0.00084297 0.1922 0.30847"
      rpy="-1.5708 0 0" />
    <parent
      link="torso_link4" />
    <child
      link="left_arm_link1" />
    <axis
      xyz="0 0 1" />
    <limit
      lower="-2.8798"
      upper="2.8798"
      effort="40"
      velocity="20.944" />
  </joint>
  <link
    name="left_arm_link2">
    <inertial>
      <origin
        xyz="-0.23622 -0.016347 -0.029968"
        rpy="0 0 0" />
      <mass
        value="1.3" />
      <inertia
        ixx="0.0075712"
        ixy="0.0"
        ixz="0.00"
        iyy="0.00075936"
        iyz="0.00"
        izz="0.0075712" />
    </inertial>
    <visual>
      <origin
        xyz="0 0 0"
        rpy="0 0 0" />
      <geometry>
        <mesh
          filename="package://mobiman/urdf/R1/meshes/left_arm_link2.STL" />
      </geometry>
      <material
        name="">
        <color
          rgba="0.79216 0.81961 0.93333 1" />
      </material>
    </visual>
    <collision>
      <origin
        xyz="0 0 0"
        rpy="0 0 0" />
      <geometry>
        <mesh
          filename="package://mobiman/urdf/R1/meshes/left_arm_link2.STL" />
      </geometry>
    </collision>
  </link>
  <joint
    name="left_arm_joint2"
    type="revolute">
    <origin
      xyz="0 0.0301 0.073007"
      rpy="-1.5708 0 0" />
    <parent
      link="left_arm_link1" />
    <child
      link="left_arm_link2" />
    <axis
      xyz="0 0 1" />
    <limit
      lower="0"
      upper="3.2289"
      effort="40"
      velocity="20.944" />
  </joint>
  <link
    name="left_arm_link3">
    <inertial>
      <origin
        xyz="0.04533 -0.054435 -0.044131"
        rpy="0 0 0" />
      <mass
        value="0.818" />
      <inertia
        ixx="0.00059585"
        ixy="0.00022591"
        ixz="7.1565E-06"
        iyy="0.0013908"
        iyz="9.6987E-06"
        izz="0.0014968" />
    </inertial>
    <visual>
      <origin
        xyz="0 0 0"
        rpy="0 0 0" />
      <geometry>
        <mesh
          filename="package://mobiman/urdf/R1/meshes/left_arm_link3.STL" />
      </geometry>
      <material
        name="">
        <color
          rgba="0.79216 0.81961 0.93333 1" />
      </material>
    </visual>
    <collision>
      <origin
        xyz="0 0 0"
        rpy="0 0 0" />
      <geometry>
        <mesh
          filename="package://mobiman/urdf/R1/meshes/left_arm_link3.STL" />
      </geometry>
    </collision>
  </link>
  <joint
    name="left_arm_joint3"
    type="revolute">
    <origin
      xyz="-0.34928 -0.019995 0.0145"
      rpy="0 0 0" />
    <parent
      link="left_arm_link2" />
    <child
      link="left_arm_link3" />
    <axis
      xyz="0 0 1" />
    <limit
      lower="-3.3161"
      upper="0"
      effort="27"
      velocity="7.5398" />
  </joint>
  <link
    name="left_arm_link4">
    <inertial>
      <origin
        xyz="8.1251E-07 -0.0021447 0.27415"
        rpy="0 0 0" />
      <mass
        value="0.816" />
      <inertia
        ixx="9.7044E-05"
        ixy="-5.3628E-09"
        ixz="-2.2365E-09"
        iyy="0.00010174"
        iyz="8.2619E-07"
        izz="8.45E-05" />
    </inertial>
    <visual>
      <origin
        xyz="0 0 0"
        rpy="0 0 0" />
      <geometry>
        <mesh
          filename="package://mobiman/urdf/R1/meshes/left_arm_link4.STL" />
      </geometry>
      <material
        name="">
        <color
          rgba="1 1 1 1" />
      </material>
    </visual>
    <collision>
      <origin
        xyz="0 0 0"
        rpy="0 0 0" />
      <geometry>
        <mesh
          filename="package://mobiman/urdf/R1/meshes/left_arm_link4.STL" />
      </geometry>
    </collision>
  </link>
  <joint
    name="left_arm_joint4"
    type="revolute">
    <origin
      xyz="-0.0039497 -0.07 -0.0446"
      rpy="0 1.5708 0" />
    <parent
      link="left_arm_link3" />
    <child
      link="left_arm_link4" />
    <axis
      xyz="0 0 1" />
    <limit
      lower="-2.8798"
      upper="2.8798"
      effort="7"
      velocity="25.133" />
  </joint>
  <link
    name="left_arm_link5">
    <inertial>
      <origin
        xyz="0.054309 -3.9656E-06 -0.021819"
        rpy="0 0 0" />
      <mass
        value="0.801" />
      <inertia
        ixx="8.4E-05"
        ixy="-7.4183E-08"
        ixz="1.6234E-05"
        iyy="0.00011333"
        iyz="1.3843E-08"
        izz="9.8498E-05" />
    </inertial>
    <visual>
      <origin
        xyz="0 0 0"
        rpy="0 0 0" />
      <geometry>
        <mesh
          filename="package://mobiman/urdf/R1/meshes/left_arm_link5.STL" />
      </geometry>
      <material
        name="">
        <color
          rgba="1 1 1 1" />
      </material>
    </visual>
    <collision>
      <origin
        xyz="0 0 0"
        rpy="0 0 0" />
      <geometry>
        <mesh
          filename="package://mobiman/urdf/R1/meshes/left_arm_link5.STL" />
      </geometry>
    </collision>
  </link>
  <joint
    name="left_arm_joint5"
    type="revolute">
    <origin
      xyz="0 -0.025267 0.2776"
      rpy="-3.1416 -1.5708 -1.5708" />
    <parent
      link="left_arm_link4" />
    <child
      link="left_arm_link5" />
    <axis
      xyz="0 0 1" />
    <limit
      lower="-1.6581"
      upper="1.6581"
      effort="7"
      velocity="25.133" />
  </joint>
  <link
    name="left_arm_link6">
    <inertial>
      <origin
        xyz="-2.6573E-06 1.5938E-07 0.034797"
        rpy="0 0 0" />
      <mass
        value="0.465" />
      <inertia
        ixx="0.00010064"
        ixy="-1.5266E-10"
        ixz="-1.3825E-08"
        iyy="9.8681E-05"
        iyz="6.9609E-10"
        izz="7.0128E-05" />
    </inertial>
    <visual>
      <origin
        xyz="0 0 0"
        rpy="0 0 0" />
      <geometry>
        <mesh
          filename="package://mobiman/urdf/R1/meshes/left_arm_link6.STL" />
      </geometry>
      <material
        name="">
        <color
          rgba="0.79216 0.81961 0.93333 1" />
      </material>
    </visual>
    <collision>
      <origin
        xyz="0 0 0"
        rpy="0 0 0" />
      <geometry>
        <mesh
          filename="package://mobiman/urdf/R1/meshes/left_arm_link6.STL" />
      </geometry>
    </collision>
  </link>
  <joint
    name="left_arm_joint6"
    type="revolute">
    <origin
      xyz="0.081499 0 -0.0255"
      rpy="-1.5708 0 -1.5708" />
    <parent
      link="left_arm_link5" />
    <child
      link="left_arm_link6" />
    <axis
      xyz="0 0 1" />
    <limit
      lower="-2.8798"
      upper="2.8798"
      effort="7"
      velocity="25.133" />
  </joint>
  <link
    name="left_gripper_link1">
    <inertial>
      <origin
        xyz="-0.024519 0.0013197 -0.0048265"
        rpy="0 0 0" />
      <mass
        value="0.057" />
      <inertia
        ixx="1.7538E-06"
        ixy="1.1806E-07"
        ixz="2.4211E-07"
        iyy="4.5917E-06"
        iyz="1.1801E-07"
        izz="5.1262E-06" />
    </inertial>
    <visual>
      <origin
        xyz="0 0 0"
        rpy="0 0 0" />
      <geometry>
        <mesh
          filename="package://mobiman/urdf/R1/meshes/left_gripper_link1.STL" />
      </geometry>
      <material
        name="">
        <color
          rgba="0.82353 0.82353 1 1" />
      </material>
    </visual>
    <collision>
      <origin
        xyz="0 0 0"
        rpy="0 0 0" />
      <geometry>
        <mesh
          filename="package://mobiman/urdf/R1/meshes/left_gripper_link1.STL" />
      </geometry>
    </collision>
  </link>
  <joint
    name="left_gripper_axis1"
    type="prismatic">
    <origin
      xyz="0 -0.0086403 0.12642"
      rpy="1.5708 -1.5708 0" />
    <parent
      link="left_arm_link6" />
    <child
      link="left_gripper_link1" />
    <axis
      xyz="0 0 1" />
    <limit
      lower="0"
      upper="0.03"
      effort="100"
      velocity="0.25" />
  </joint>
  <link
    name="left_gripper_link2">
    <inertial>
      <origin
        xyz="-0.02434 0.0018486 -0.0048904"
        rpy="0 0 0" />
      <mass
        value="0.057" />
      <inertia
        ixx="1.7319E-06"
        ixy="2.0993E-07"
        ixz="2.2615E-07"
        iyy="4.4865E-06"
        iyz="1.0434E-07"
        izz="5.0068E-06" />
    </inertial>
    <visual>
      <origin
        xyz="0 0 0"
        rpy="0 0 0" />
      <geometry>
        <mesh
          filename="package://mobiman/urdf/R1/meshes/left_gripper_link2.STL" />
      </geometry>
      <material
        name="">
        <color
          rgba="0.82353 0.82353 1 1" />
      </material>
    </visual>
    <collision>
      <origin
        xyz="0 0 0"
        rpy="0 0 0" />
      <geometry>
        <mesh
          filename="package://mobiman/urdf/R1/meshes/left_gripper_link2.STL" />
      </geometry>
    </collision>
  </link>
  <joint
    name="left_gripper_axis2"
    type="prismatic">
    <origin
      xyz="-0.00076771 0.0086403 0.12641"
      rpy="1.5708 -1.5708 3.1416" />
    <parent
      link="left_arm_link6" />
    <child
      link="left_gripper_link2" />
    <axis
      xyz="0 0 1" />
    <limit
      lower="0"
      upper="0.03"
      effort="100"
      velocity="0.25" />
  </joint>
  <link
    name="right_arm_link1">
    <inertial>
      <origin
        xyz="0.025904 0.089421 0.19171"
        rpy="0 0 0" />
      <mass
        value="1.319" />
      <inertia
        ixx="0.00058101"
        ixy="-7.5672E-09"
        ixz="-2.9207E-08"
        iyy="0.00070857"
        iyz="8.5639E-07"
        izz="0.00044583" />
    </inertial>
    <visual>
      <origin
        xyz="0 0 0"
        rpy="0 0 0" />
      <geometry>
        <mesh
          filename="package://mobiman/urdf/R1/meshes/right_arm_link1.STL" />
      </geometry>
      <material
        name="">
        <color
          rgba="0.79216 0.81961 0.93333 1" />
      </material>
    </visual>
    <collision>
      <origin
        xyz="0 0 0"
        rpy="0 0 0" />
      <geometry>
        <mesh
          filename="package://mobiman/urdf/R1/meshes/right_arm_link1.STL" />
      </geometry>
    </collision>
  </link>
  <joint
    name="right_arm_joint1"
    type="revolute">
    <origin
      xyz="-0.00084297 -0.1922 0.30847"
      rpy="1.5708 0 0" />
    <parent
      link="torso_link4" />
    <child
      link="right_arm_link1" />
    <axis
      xyz="0 0 1" />
    <limit
      lower="-2.8798"
      upper="2.8798"
      effort="40"
      velocity="20.944" />
  </joint>
  <link
    name="right_arm_link2">
    <inertial>
      <origin
        xyz="-0.23622 -0.016347 -0.029968"
        rpy="0 0 0" />
      <mass
        value="1.3" />
      <inertia
        ixx="0.00060639"
        ixy="-0.00041823"
        ixz="-0.00014957"
        iyy="0.0075936"
        iyz="-8.0938E-06"
        izz="0.0075712" />
    </inertial>
    <visual>
      <origin
        xyz="0 0 0"
        rpy="0 0 0" />
      <geometry>
        <mesh
          filename="package://mobiman/urdf/R1/meshes/right_arm_link2.STL" />
      </geometry>
      <material
        name="">
        <color
          rgba="0.79216 0.81961 0.93333 1" />
      </material>
    </visual>
    <collision>
      <origin
        xyz="0 0 0"
        rpy="0 0 0" />
      <geometry>
        <mesh
          filename="package://mobiman/urdf/R1/meshes/right_arm_link2.STL" />
      </geometry>
    </collision>
  </link>
  <joint
    name="right_arm_joint2"
    type="revolute">
    <origin
      xyz="0 0.0301 0.073007"
      rpy="-1.5708 0 0" />
    <parent
      link="right_arm_link1" />
    <child
      link="right_arm_link2" />
    <axis
      xyz="0 0 1" />
    <limit
      lower="0"
      upper="3.2289"
      effort="40"
      velocity="20.944" />
  </joint>
  <link
    name="right_arm_link3">
    <inertial>
      <origin
        xyz="0.04533 -0.054435 -0.044131"
        rpy="0 0 0" />
      <mass
        value="0.818" />
      <inertia
        ixx="0.00059585"
        ixy="0.00022591"
        ixz="7.1567E-06"
        iyy="0.0013908"
        iyz="-9.6986E-06"
        izz="0.0014968" />
    </inertial>
    <visual>
      <origin
        xyz="0 0 0"
        rpy="0 0 0" />
      <geometry>
        <mesh
          filename="package://mobiman/urdf/R1/meshes/right_arm_link3.STL" />
      </geometry>
      <material
        name="">
        <color
          rgba="0.79216 0.81961 0.93333 1" />
      </material>
    </visual>
    <collision>
      <origin
        xyz="0 0 0"
        rpy="0 0 0" />
      <geometry>
        <mesh
          filename="package://mobiman/urdf/R1/meshes/right_arm_link3.STL" />
      </geometry>
    </collision>
  </link>
  <joint
    name="right_arm_joint3"
    type="revolute">
    <origin
      xyz="-0.34928 -0.019995 0.0145"
      rpy="0 0 0" />
    <parent
      link="right_arm_link2" />
    <child
      link="right_arm_link3" />
    <axis
      xyz="0 0 1" />
    <limit
      lower="-3.3161"
      upper="0"
      effort="27"
      velocity="7.5398" />
  </joint>
  <link
    name="right_arm_link4">
    <inertial>
      <origin
        xyz="-8.1251E-07 0.0021447 0.27415"
        rpy="0 0 0" />
      <mass
        value="0.816" />
      <inertia
        ixx="9.7044E-05"
        ixy="-5.3628E-09"
        ixz="2.2365E-09"
        iyy="0.00010174"
        iyz="-8.2619E-07"
        izz="8.45E-05" />
    </inertial>
    <visual>
      <origin
        xyz="0 0 0"
        rpy="0 0 0" />
      <geometry>
        <mesh
          filename="package://mobiman/urdf/R1/meshes/right_arm_link4.STL" />
      </geometry>
      <material
        name="">
        <color
          rgba="1 1 1 1" />
      </material>
    </visual>
    <collision>
      <origin
        xyz="0 0 0"
        rpy="0 0 0" />
      <geometry>
        <mesh
          filename="package://mobiman/urdf/R1/meshes/right_arm_link4.STL" />
      </geometry>
    </collision>
  </link>
  <joint
    name="right_arm_joint4"
    type="revolute">
    <origin
      xyz="-0.0039497 -0.07 -0.0446"
      rpy="1.5708 -1.5708 1.5708" />
    <parent
      link="right_arm_link3" />
    <child
      link="right_arm_link4" />
    <axis
      xyz="0 0 1" />
    <limit
      lower="-2.8798"
      upper="2.8798"
      effort="7"
      velocity="25.133" />
  </joint>
  <link
    name="right_arm_link5">
    <inertial>
      <origin
        xyz="0.054309 -3.9656E-06 -0.021819"
        rpy="0 0 0" />
      <mass
        value="0.801" />
      <inertia
        ixx="8.4E-05"
        ixy="-7.4183E-08"
        ixz="1.6234E-05"
        iyy="0.00011333"
        iyz="1.3843E-08"
        izz="9.8498E-05" />
    </inertial>
    <visual>
      <origin
        xyz="0 0 0"
        rpy="0 0 0" />
      <geometry>
        <mesh
          filename="package://mobiman/urdf/R1/meshes/right_arm_link5.STL" />
      </geometry>
      <material
        name="">
        <color
          rgba="1 1 1 1" />
      </material>
    </visual>
    <collision>
      <origin
        xyz="0 0 0"
        rpy="0 0 0" />
      <geometry>
        <mesh
          filename="package://mobiman/urdf/R1/meshes/right_arm_link5.STL" />
      </geometry>
    </collision>
  </link>
  <joint
    name="right_arm_joint5"
    type="revolute">
    <origin
      xyz="0 0.025267 0.2776"
      rpy="3.1416 -1.5708 1.5708" />
    <parent
      link="right_arm_link4" />
    <child
      link="right_arm_link5" />
    <axis
      xyz="0 0 1" />
    <limit
      lower="-1.6581"
      upper="1.6581"
      effort="7"
      velocity="25.133" />
  </joint>
  <link
    name="right_arm_link6">
    <inertial>
      <origin
        xyz="2.5842E-06 -8.3168E-08 0.034797"
        rpy="0 0 0" />
      <mass
        value="0.465" />
      <inertia
        ixx="0.00010064"
        ixy="-1.6381E-10"
        ixz="1.3876E-08"
        iyy="9.8681E-05"
        iyz="-7.3374E-10"
        izz="7.0128E-05" />
    </inertial>
    <visual>
      <origin
        xyz="0 0 0"
        rpy="0 0 0" />
      <geometry>
        <mesh
          filename="package://mobiman/urdf/R1/meshes/right_arm_link6.STL" />
      </geometry>
      <material
        name="">
        <color
          rgba="0.79216 0.81961 0.93333 1" />
      </material>
    </visual>
    <collision>
      <origin
        xyz="0 0 0"
        rpy="0 0 0" />
      <geometry>
        <mesh
          filename="package://mobiman/urdf/R1/meshes/right_arm_link6.STL" />
      </geometry>
    </collision>
  </link>
  <joint
    name="right_arm_joint6"
    type="revolute">
    <origin
      xyz="0.081499 0 -0.0255"
      rpy="1.5708 0 1.5708" />
    <parent
      link="right_arm_link5" />
    <child
      link="right_arm_link6" />
    <axis
      xyz="0 0 1" />
    <limit
      lower="-2.8798"
      upper="2.8798"
      effort="7"
      velocity="25.133" />
  </joint>
  <link
    name="right_gripper_link1">
    <inertial>
      <origin
        xyz="-0.024364 0.0014241 -0.0048851"
        rpy="0 0 0" />
      <mass
        value="0.057" />
      <inertia
        ixx="1.7312E-06"
        ixy="1.5869E-07"
        ixz="2.2744E-07"
        iyy="4.5003E-06"
        iyz="1.1134E-07"
        izz="5.019E-06" />
    </inertial>
    <visual>
      <origin
        xyz="0 0 0"
        rpy="0 0 0" />
      <geometry>
        <mesh
          filename="package://mobiman/urdf/R1/meshes/right_gripper_link1.STL" />
      </geometry>
      <material
        name="">
        <color
          rgba="0.82353 0.82353 1 1" />
      </material>
    </visual>
    <collision>
      <origin
        xyz="0 0 0"
        rpy="0 0 0" />
      <geometry>
        <mesh
          filename="package://mobiman/urdf/R1/meshes/right_gripper_link1.STL" />
      </geometry>
    </collision>
  </link>
  <joint
    name="right_gripper_axis1"
    type="prismatic">
    <origin
      xyz="0 0.0086405 0.12642"
      rpy="2.3562 -1.5708 2.3562" />
    <parent
      link="right_arm_link6" />
    <child
      link="right_gripper_link1" />
    <axis
      xyz="0 0 1" />
    <limit
      lower="0"
      upper="0.03"
      effort="100"
      velocity="0.25" />
  </joint>
  <link
    name="right_gripper_link2">
    <inertial>
      <origin
        xyz="-0.024307 0.0018804 -0.0048959"
        rpy="0 0 0" />
      <mass
        value="0.057" />
      <inertia
        ixx="1.7246E-06"
        ixy="2.2124E-07"
        ixz="2.2686E-07"
        iyy="4.469E-06"
        iyz="1.0423E-07"
        izz="4.9835E-06" />
    </inertial>
    <visual>
      <origin
        xyz="0 0 0"
        rpy="0 0 0" />
      <geometry>
        <mesh
          filename="package://mobiman/urdf/R1/meshes/right_gripper_link2.STL" />
      </geometry>
      <material
        name="">
        <color
          rgba="0.82353 0.82353 1 1" />
      </material>
    </visual>
    <collision>
      <origin
        xyz="0 0 0"
        rpy="0 0 0" />
      <geometry>
        <mesh
          filename="package://mobiman/urdf/R1/meshes/right_gripper_link2.STL" />
      </geometry>
    </collision>
  </link>
  <joint
    name="right_gripper_axis2"
    type="prismatic">
    <origin
      xyz="0.00076746 -0.00864 0.12641"
      rpy="-0.78541 -1.5708 2.3562" />
    <parent
      link="right_arm_link6" />
    <child
      link="right_gripper_link2" />
    <axis
      xyz="0 0 1" />
    <limit
      lower="0"
      upper="0.03"
      effort="100"
      velocity="0.25" />
  </joint>
</robot>