<?xml version="1.0" ?>
<!-- =================================================================================== -->
<!-- |    This document was autogenerated by xacro from urdf/x1_dvt.xacro              | -->
<!-- |    EDITING THIS FILE BY HAND IS NOT RECOMMENDED                                 | -->
<!-- =================================================================================== -->
<robot name="x1_dvt">
  <mujoco>
    <compiler meshdir="../meshes"/>
  </mujoco>
  <transmission name="steer_rl_tran">
    <type>transmission_interface/SimpleTransmission</type>
    <joint name="steer_rl_joint">
      <hardwareInterface>hardware_interface/PositionJointInterface</hardwareInterface>
    </joint>
    <actuator name="steer_rl_actr">
      <hardwareInterface>hardware_interface/PositionJointInterface</hardwareInterface>
      <mechanicalReduction>1</mechanicalReduction>
    </actuator>
  </transmission>
  <transmission name="steer_rr_tran">
    <type>transmission_interface/SimpleTransmission</type>
    <joint name="steer_rr_joint">
      <hardwareInterface>hardware_interface/PositionJointInterface</hardwareInterface>
    </joint>
    <actuator name="steer_rr_actr">
      <hardwareInterface>hardware_interface/PositionJointInterface</hardwareInterface>
      <mechanicalReduction>1</mechanicalReduction>
    </actuator>
  </transmission>
  <transmission name="steer_fl_tran">
    <type>transmission_interface/SimpleTransmission</type>
    <joint name="steer_fl_joint">
      <hardwareInterface>hardware_interface/PositionJointInterface</hardwareInterface>
    </joint>
    <actuator name="steer_fl_actr">
      <hardwareInterface>hardware_interface/PositionJointInterface</hardwareInterface>
      <mechanicalReduction>1</mechanicalReduction>
    </actuator>
  </transmission>
  <transmission name="steer_fr_tran">
    <type>transmission_interface/SimpleTransmission</type>
    <joint name="steer_fr_joint">
      <hardwareInterface>hardware_interface/PositionJointInterface</hardwareInterface>
    </joint>
    <actuator name="steer_fr_actr">
      <hardwareInterface>hardware_interface/PositionJointInterface</hardwareInterface>
      <mechanicalReduction>1</mechanicalReduction>
    </actuator>
  </transmission>
  <transmission name="wheel_rl_tran">
    <type>transmission_interface/SimpleTransmission</type>
    <joint name="wheel_rl_joint">
      <hardwareInterface>hardware_interface/VelocityJointInterface</hardwareInterface>
    </joint>
    <actuator name="wheelrl_actr">
      <hardwareInterface>hardware_interface/VelocityJointInterface</hardwareInterface>
      <mechanicalReduction>1</mechanicalReduction>
    </actuator>
  </transmission>
  <transmission name="wheel_rr_tran">
    <type>transmission_interface/SimpleTransmission</type>
    <joint name="wheel_rr_joint">
      <hardwareInterface>hardware_interface/VelocityJointInterface</hardwareInterface>
    </joint>
    <actuator name="wheel_rr_actr">
      <hardwareInterface>hardware_interface/VelocityJointInterface</hardwareInterface>
      <mechanicalReduction>1</mechanicalReduction>
    </actuator>
  </transmission>
  <transmission name="wheel_fr_tran">
    <type>transmission_interface/SimpleTransmission</type>
    <joint name="wheel_fr_joint">
      <hardwareInterface>hardware_interface/VelocityJointInterface</hardwareInterface>
    </joint>
    <actuator name="wheel_fr_actr">
      <hardwareInterface>hardware_interface/VelocityJointInterface</hardwareInterface>
      <mechanicalReduction>1</mechanicalReduction>
    </actuator>
  </transmission>
  <transmission name="wheel_fl_tran">
    <type>transmission_interface/SimpleTransmission</type>
    <joint name="wheel_fl_joint">
      <hardwareInterface>hardware_interface/VelocityJointInterface</hardwareInterface>
    </joint>
    <actuator name="wheel_fl_actr">
      <hardwareInterface>hardware_interface/VelocityJointInterface</hardwareInterface>
      <mechanicalReduction>1</mechanicalReduction>
    </actuator>
  </transmission>
  <gazebo>
    <plugin filename="libgazebo_ros_control.so" name="control"/>
    <plugin filename="libgazebo_ros_p3d.so" name="ground_truth">
      <alwaysOn>true</alwaysOn>
      <updateRate>50.0</updateRate>
      <bodyName>body</bodyName>
      <topicName>ground_truth/state</topicName>
      <!-- <gaussianNoise>0.00</gaussianNoise> -->
      <frameName>world</frameName>
      <xyzOffsets>0 0 0</xyzOffsets>
      <rpyOffsets>0 0 0</rpyOffsets>
    </plugin>
  </gazebo>
  <gazebo reference="body">
    <material>Gazebo/Silver</material>
    <selfCollide>true</selfCollide>
  </gazebo>
  <gazebo reference="steer_fl">
    <material>Gazebo/Grey</material>
    <selfCollide>false</selfCollide>
  </gazebo>
  <gazebo reference="steer_fr">
    <material>Gazebo/Grey</material>
    <selfCollide>false</selfCollide>
  </gazebo>
  <gazebo reference="steer_rl">
    <material>Gazebo/Grey</material>
    <selfCollide>false</selfCollide>
  </gazebo>
  <gazebo reference="steer_rr">
    <material>Gazebo/Grey</material>
    <selfCollide>false</selfCollide>
  </gazebo>
  <gazebo reference="wheel_fl">
    <material>Gazebo/DarkGrey</material>
    <mu1>0.6</mu1>
    <mu2>0.8</mu2>
    <selfCollide>false</selfCollide>
  </gazebo>
  <gazebo reference="wheel_fr">
    <material>Gazebo/DarkGrey</material>
    <mu1>0.6</mu1>
    <mu2>0.8</mu2>
    <selfCollide>false</selfCollide>
  </gazebo>
  <gazebo reference="wheel_rl">
    <material>Gazebo/DarkGrey</material>
    <mu1>0.6</mu1>
    <mu2>0.8</mu2>
    <selfCollide>false</selfCollide>
  </gazebo>
  <gazebo reference="wheel_rr">
    <material>Gazebo/DarkGrey</material>
    <mu1>0.6</mu1>
    <mu2>0.8</mu2>
    <selfCollide>false</selfCollide>
  </gazebo>
  <link name="body">
    <inertial>
      <origin rpy="0 0 0" xyz="0.0201415326881475 -0.00376360713973977 0.231535867234874"/>
      <mass value="30.5"/>
      <inertia ixx="0.678285613847468" ixy="-0.002416513" ixz="0.0022494489" iyy="0.633385400402055" iyz="0.0005681185" izz="0.839876429363137"/>
    </inertial>
    <visual>
      <origin rpy="0 0 0" xyz="0 0 0"/>
      <geometry>
        <mesh filename="package://x1_dvt_description/meshes/body.STL"/>
      </geometry>
      <material name="">
        <color rgba="0.694117647058824 0.694117647058824 0.694117647058824 1"/>
      </material>
    </visual>
    <collision>
      <origin rpy="0 0 0" xyz="0 0 0.141"/>
      <geometry>
        <box size="0.440 0.176 0.108"/>
      </geometry>
    </collision>
    <collision>
      <origin rpy="0 0 0" xyz="0 0 0.141"/>
      <geometry>
        <box size="0.176 0.440 0.108"/>
      </geometry>
    </collision>
    <collision>
      <origin rpy="0 0 0" xyz="0 0 0.280"/>
      <geometry>
        <box size="0.470 0.470 0.170"/>
      </geometry>
    </collision>
    <collision>
      <origin rpy="0 0 0" xyz="0 0 0.4"/>
      <geometry>
        <box size="0.28 0.14 0.8"/>
      </geometry>
    </collision>
    <collision>
      <origin rpy="0 0 0" xyz="0 0 0.81"/>
      <geometry>
        <box size="0.47 0.46 0.01"/>
      </geometry>
    </collision>
    <collision>
      <origin xyz="0 0 1.013009957196532"/>
      <geometry>
        <box size="0.09 0.12 0.4"/>
      </geometry>
    </collision>
  </link>
  <link name="steer_fl">
    <inertial>
      <origin rpy="0 0 0" xyz="-0.00691156729394696 -0.0420834987275499 -0.0817054968882958"/>
      <mass value="0.264569175125124"/>
      <inertia ixx="0.000149108673497983" ixy="-1.66665001523996E-06" ixz="7.98442367353238E-06" iyy="0.000193413137013324" iyz="1.17261835653715E-07" izz="0.000183444142505049"/>
    </inertial>
    <visual>
      <origin rpy="0 0 0" xyz="0 0 0"/>
      <geometry>
        <mesh filename="package://x1_dvt_description/meshes/steer_fl.STL"/>
      </geometry>
      <material name="">
        <color rgba="0.792156862745098 0.819607843137255 0.933333333333333 1"/>
      </material>
    </visual>
    <!-- <collision>
      <origin
        xyz="0 0 0"
        rpy="0 0 0" />
      <geometry>
        <mesh
          filename="package://x1_dvt_description/meshes/steer_fl.STL" />
      </geometry>
    </collision> -->
  </link>
  <joint name="steer_fl_joint" type="continuous">
    <origin rpy="0 0 0" xyz="0.187383297014435 0.187383297014435 0.190009957196532"/>
    <parent link="body"/>
    <child link="steer_fl"/>
    <axis xyz="0 0 1"/>
  </joint>
  <link name="wheel_fl">
    <inertial>
      <origin rpy="0 0 0" xyz="-2.22885015999097E-10 -0.0236245498306882 1.51825385596993E-10"/>
      <mass value="0.767242700918225"/>
      <inertia ixx="0.000998348156514368" ixy="7.46246244639827E-10" ixz="2.20517262492705E-08" iyy="0.00159574095024866" iyz="-2.11390635305776E-10" izz="0.000998326469362249"/>
    </inertial>
    <visual>
      <origin rpy="0 0 0" xyz="0 0 0"/>
      <geometry>
        <mesh filename="package://x1_dvt_description/meshes/wheel_fl.STL"/>
      </geometry>
      <material name="">
        <color rgba="0.4 0.4 0.4 1"/>
      </material>
    </visual>
    <collision>
      <origin rpy="1.5707963 0 0" xyz="0 -0.024 0"/>
      <geometry>
        <cylinder length="0.04" radius="0.07"/>
      </geometry>
    </collision>
  </link>
  <joint name="wheel_fl_joint" type="continuous">
    <origin rpy="0 0 0" xyz="0.00327510876924406 0.0255 -0.120034354832183"/>
    <parent link="steer_fl"/>
    <child link="wheel_fl"/>
    <axis xyz="0 1 0"/>
  </joint>
  <link name="steer_fr">
    <inertial>
      <origin rpy="0 0 0" xyz="-0.00689963411124106 0.0421434119864407 -0.0817244752289895"/>
      <mass value="0.264485802311604"/>
      <inertia ixx="0.000148947199406975" ixy="8.10415224096045E-07" ixz="7.98491575932754E-06" iyy="0.00019329183141186" iyz="8.58489128063935E-08" izz="0.000183162746698183"/>
    </inertial>
    <visual>
      <origin rpy="0 0 0" xyz="0 0 0"/>
      <geometry>
        <mesh filename="package://x1_dvt_description/meshes/steer_fr.STL"/>
      </geometry>
      <material name="">
        <color rgba="0.627450980392157 0.627450980392157 0.627450980392157 1"/>
      </material>
    </visual>
    <!-- <collision>
      <origin
        xyz="0 0 0"
        rpy="0 0 0" />
      <geometry>
        <mesh
          filename="package://x1_dvt_description/meshes/steer_fr.STL" />
      </geometry>
    </collision> -->
  </link>
  <joint name="steer_fr_joint" type="continuous">
    <origin rpy="0 0 0" xyz="0.187383297014435 -0.187383297014436 0.190009957196532"/>
    <parent link="body"/>
    <child link="steer_fr"/>
    <axis xyz="0 0 1"/>
  </joint>
  <link name="wheel_fr">
    <inertial>
      <origin rpy="0 0 0" xyz="-2.68730815378149E-10 0.0236245498327907 -1.29364990941738E-11"/>
      <mass value="0.76724270085018"/>
      <inertia ixx="0.000998322335269615" ixy="-7.45350341020908E-10" ixz="-1.9481624857262E-08" iyy="0.00159574095021819" iyz="2.14445413542528E-10" izz="0.000998352290490362"/>
    </inertial>
    <visual>
      <origin rpy="0 0 0" xyz="0 0 0"/>
      <geometry>
        <mesh filename="package://x1_dvt_description/meshes/wheel_fr.STL"/>
      </geometry>
      <material name="">
        <color rgba="0.4 0.4 0.4 1"/>
      </material>
    </visual>
    <collision>
      <origin rpy="1.5707963 0 0" xyz="0 0.024 0"/>
      <geometry>
        <cylinder length="0.04" radius="0.07"/>
      </geometry>
    </collision>
  </link>
  <joint name="wheel_fr_joint" type="continuous">
    <origin rpy="0 0 0" xyz="0.00327510876924395 -0.0255 -0.120034354832183"/>
    <parent link="steer_fr"/>
    <child link="wheel_fr"/>
    <axis xyz="0 1 0"/>
  </joint>
  <link name="steer_rl">
    <inertial>
      <origin rpy="0 0 0" xyz="0.006899634111241 -0.0421434119864406 -0.0817244752289895"/>
      <mass value="0.264485802311604"/>
      <inertia ixx="0.000148947199406975" ixy="8.104152240961E-07" ixz="-7.98491575932753E-06" iyy="0.00019329183141186" iyz="-8.58489128063896E-08" izz="0.000183162746698183"/>
    </inertial>
    <visual>
      <origin rpy="0 0 0" xyz="0 0 0"/>
      <geometry>
        <mesh filename="package://x1_dvt_description/meshes/steer_rl.STL"/>
      </geometry>
      <material name="">
        <color rgba="0.627450980392157 0.627450980392157 0.627450980392157 1"/>
      </material>
    </visual>
    <!-- <collision>
      <origin
        xyz="0 0 0"
        rpy="0 0 0" />
      <geometry>
        <mesh
          filename="package://x1_dvt_description/meshes/steer_rl.STL" />
      </geometry>
    </collision> -->
  </link>
  <joint name="steer_rl_joint" type="continuous">
    <origin rpy="0 0 0" xyz="-0.187383297014435 0.187383297014436 0.190009957196532"/>
    <parent link="body"/>
    <child link="steer_rl"/>
    <axis xyz="0 0 1"/>
  </joint>
  <link name="wheel_rl">
    <inertial>
      <origin rpy="0 0 0" xyz="2.68730815378149E-10 -0.0236245498327907 -1.29365407275372E-11"/>
      <mass value="0.767242700850179"/>
      <inertia ixx="0.000998322335269613" ixy="-7.45350339388292E-10" ixz="1.94816248573348E-08" iyy="0.00159574095021819" iyz="-2.1444541408325E-10" izz="0.00099835229049036"/>
    </inertial>
    <visual>
      <origin rpy="0 0 0" xyz="0 0 0"/>
      <geometry>
        <mesh filename="package://x1_dvt_description/meshes/wheel_rl.STL"/>
      </geometry>
      <material name="">
        <color rgba="0.4 0.4 0.4 1"/>
      </material>
    </visual>
    <collision>
      <origin rpy="1.5707963 0 0" xyz="0 -0.024 0"/>
      <geometry>
        <cylinder length="0.04" radius="0.07"/>
      </geometry>
    </collision>
  </link>
  <joint name="wheel_rl_joint" type="continuous">
    <origin rpy="0 0 0" xyz="-0.00327510876924392 0.0255 -0.120034354832183"/>
    <parent link="steer_rl"/>
    <child link="wheel_rl"/>
    <axis xyz="0 1 0"/>
  </joint>
  <link name="steer_rr">
    <inertial>
      <origin rpy="0 0 0" xyz="0.00691156729394826 0.0420834987275485 -0.0817054968882964"/>
      <mass value="0.264569175125124"/>
      <inertia ixx="0.000149108673497984" ixy="-1.66665001523981E-06" ixz="-7.98442367353275E-06" iyy="0.000193413137013324" iyz="-1.17261835653865E-07" izz="0.000183444142505049"/>
    </inertial>
    <visual>
      <origin rpy="0 0 0" xyz="0 0 0"/>
      <geometry>
        <mesh filename="package://x1_dvt_description/meshes/steer_rr.STL"/>
      </geometry>
      <material name="">
        <color rgba="0.792156862745098 0.819607843137255 0.933333333333333 1"/>
      </material>
    </visual>
    <!-- <collision>
      <origin
        xyz="0 0 0"
        rpy="0 0 0" />
      <geometry>
        <mesh
          filename="package://x1_dvt_description/meshes/steer_rr.STL" />
      </geometry>
    </collision> -->
  </link>
  <joint name="steer_rr_joint" type="continuous">
    <origin rpy="0 0 0" xyz="-0.187383297014436 -0.187383297014434 0.190009957196532"/>
    <parent link="body"/>
    <child link="steer_rr"/>
    <axis xyz="0 0 1"/>
  </joint>
  <link name="wheel_rr">
    <inertial>
      <origin rpy="0 0 0" xyz="2.22885099265824E-10 0.0236245498306882 1.51825010896722E-10"/>
      <mass value="0.767242700918223"/>
      <inertia ixx="0.000998348156514364" ixy="7.46246248469878E-10" ixz="-2.20517262494765E-08" iyy="0.00159574095024865" iyz="2.11390625779751E-10" izz="0.000998326469362246"/>
    </inertial>
    <visual>
      <origin rpy="0 0 0" xyz="0 0 0"/>
      <geometry>
        <mesh filename="package://x1_dvt_description/meshes/wheel_rr.STL"/>
      </geometry>
      <material name="">
        <color rgba="0.4 0.4 0.4 1"/>
      </material>
    </visual>
    <collision>
      <origin rpy="1.5707963 0 0" xyz="0 0.024 0"/>
      <geometry>
        <cylinder length="0.04" radius="0.07"/>
      </geometry>
    </collision>
  </link>
  <joint name="wheel_rr_joint" type="continuous">
    <origin rpy="0 0 0" xyz="-0.00327510876924275 -0.0255000000000019 -0.120034354832183"/>
    <parent link="steer_rr"/>
    <child link="wheel_rr"/>
    <axis xyz="0 1 0"/>
  </joint>
  <link name="arm_seg1">
    <inertial>
      <origin rpy="0 0 0" xyz="0.00059982 -9.2932E-05 0.043301"/>
      <mass value="0.61127"/>
      <inertia ixx="0.00080212" ixy="3.0281E-06" ixz="-2.8747E-05" iyy="0.00080502" iyz="1.9749E-06" izz="0.00066167"/>
    </inertial>
    <visual>
      <origin rpy="0 0 0" xyz="0 0 0"/>
      <geometry>
        <mesh filename="package://x1_dvt_description/meshes/arm_seg1.STL"/>
      </geometry>
      <material name="">
        <color rgba="1 1 0.9451 1"/>
      </material>
    </visual>
    <!-- <collision>
    <origin
      xyz="0 0 0"
      rpy="0 0 0" />
    <geometry>
      <mesh
        filename="package://x1_dvt_description/meshes/arm_seg1.STL" />
    </geometry>
  </collision> -->
    <collision>
      <origin rpy="0 0 0" xyz="0 0 0.055"/>
      <geometry>
        <cylinder length="0.11" radius="0.06"/>
      </geometry>
    </collision>
  </link>
  <joint name="arm_base_fixed" type="fixed">
    <origin rpy="0 0 3.14159265359" xyz="0.1599 -0.16 0.813009957196532"/>
    <parent link="body"/>
    <child link="arm_seg1"/>
    <axis xyz="0 0 0"/>
  </joint>
  <link name="arm_seg2">
    <inertial>
      <origin rpy="0 0 0" xyz="-0.022858 -2.0784E-06 -0.013658"/>
      <mass value="0.74247"/>
      <inertia ixx="0.00081398" ixy="-1.9024E-05" ixz="0.00022746" iyy="0.001848" iyz="2.0444E-06" izz="0.0015286"/>
    </inertial>
    <visual>
      <origin rpy="0 0 0" xyz="0 0 0"/>
      <geometry>
        <mesh filename="package://x1_dvt_description/meshes/arm_seg2.STL"/>
      </geometry>
      <material name="">
        <color rgba="1 1 0.9451 1"/>
      </material>
    </visual>
    <collision>
      <origin rpy="0 0 0" xyz="0 0 -0.01"/>
      <geometry>
        <cylinder length="0.08" radius="0.05"/>
      </geometry>
    </collision>
    <collision>
      <origin rpy="1.57 0 0" xyz="-0.085 -0.0 0.0"/>
      <geometry>
        <cylinder length="0.03" radius="0.043"/>
      </geometry>
    </collision>
  </link>
  <joint name="seg1_to_seg2" type="revolute">
    <origin rpy="0 0 0" xyz="0 0 0.1625"/>
    <parent link="arm_seg1"/>
    <child link="arm_seg2"/>
    <axis xyz="0 0 1"/>
    <limit effort="100" lower="-3.1923" upper="3.1923" velocity="1"/>
  </joint>
  <link name="arm_seg3">
    <inertial>
      <origin rpy="0 0 0" xyz="-1.6049E-06 0.10336 0.067332"/>
      <mass value="1.3502"/>
      <inertia ixx="0.012821" ixy="-7.2979E-08" ixz="1.1499E-08" iyy="0.0011237" iyz="-0.00033755" izz="0.012933"/>
    </inertial>
    <visual>
      <origin rpy="0 0 0" xyz="0 0 0"/>
      <geometry>
        <mesh filename="package://x1_dvt_description/meshes/arm_seg3.STL"/>
      </geometry>
      <material name="">
        <color rgba="1 1 0.9451 1"/>
      </material>
    </visual>
    <collision>
      <origin rpy="0 0 0" xyz="0 0 0.05"/>
      <geometry>
        <cylinder length="0.06" radius="0.043"/>
      </geometry>
    </collision>
    <collision>
      <origin rpy="0 0 0" xyz="0 0.26 0.06"/>
      <geometry>
        <cylinder length="0.06" radius="0.04"/>
      </geometry>
    </collision>
    <collision>
      <origin rpy="0 0 0" xyz="0 0.13 0.075"/>
      <geometry>
        <box size="0.08 0.3 0.05"/>
      </geometry>
    </collision>
  </link>
  <joint name="seg2_to_seg3" type="revolute">
    <origin rpy="1.5708 0 0" xyz="-0.086 0 0"/>
    <parent link="arm_seg2"/>
    <child link="arm_seg3"/>
    <axis xyz="0 0 -1"/>
    <limit effort="100" lower="-2.61666" upper="2.442" velocity="1"/>
  </joint>
  <link name="arm_seg4">
    <inertial>
      <origin rpy="0 0 0" xyz="0.10374 7.0495E-07 0.018599"/>
      <mass value="1.0422"/>
      <inertia ixx="0.00084115" ixy="-2.2514E-08" ixz="-0.00068613" iyy="0.0094046" iyz="-3.3287E-09" izz="0.0092482"/>
    </inertial>
    <visual>
      <origin rpy="0 0 0" xyz="0 0 0"/>
      <geometry>
        <mesh filename="package://x1_dvt_description/meshes/arm_seg4.STL"/>
      </geometry>
      <material name="">
        <color rgba="1 1 0.9451 1"/>
      </material>
    </visual>
    <collision>
      <origin rpy="0 0 0" xyz="0 0 0.01"/>
      <geometry>
        <cylinder length="0.08" radius="0.04"/>
      </geometry>
    </collision>
    <collision>
      <origin rpy="0 0 0" xyz="0.24 0.0 0.015"/>
      <geometry>
        <cylinder length="0.06" radius="0.03"/>
      </geometry>
    </collision>
    <collision>
      <origin rpy="0 0 0" xyz="0.115 0.0 0.03"/>
      <geometry>
        <box size="0.23 0.05 0.04"/>
      </geometry>
    </collision>
  </link>
  <joint name="seg3_to_seg4" type="revolute">
    <origin rpy="3.1416 0 1.5708" xyz="0 0.26 0"/>
    <parent link="arm_seg3"/>
    <child link="arm_seg4"/>
    <axis xyz="0 0 1"/>
    <limit effort="100" lower="-2.61666" upper="2.61666" velocity="1"/>
  </joint>
  <link name="arm_seg5">
    <inertial>
      <origin rpy="0 0 0" xyz="-0.0069819 -0.016328 0.0067416"/>
      <mass value="0.27383"/>
      <inertia ixx="0.000248427348125803" ixy="-2.69070466966384E-09" ixz="-5.90189683029083E-09" iyy="0.000218888641767819" iyz="-3.60301322109781E-05" izz="0.000152947684409233"/>
    </inertial>
    <visual>
      <origin rpy="0 0 0" xyz="0 0 0"/>
      <geometry>
        <mesh filename="package://x1_dvt_description/meshes/arm_seg5.STL"/>
      </geometry>
      <material name="">
        <color rgba="1 1 0.9451 1"/>
      </material>
    </visual>
    <collision>
      <origin rpy="0 0 0" xyz="0 0 0.02"/>
      <geometry>
        <cylinder length="0.05" radius="0.03"/>
      </geometry>
    </collision>
    <collision>
      <origin rpy="1.57 0 0" xyz="0. -0.03 -0.0"/>
      <geometry>
        <cylinder length="0.06" radius="0.03"/>
      </geometry>
    </collision>
    <collision>
      <origin rpy="1.57 0 0" xyz="0. -0.0 -0.0"/>
      <geometry>
        <sphere radius="0.03"/>
      </geometry>
    </collision>
  </link>
  <joint name="seg4_to_seg5" type="revolute">
    <origin rpy="0 0 1.5708" xyz="0.24 0 -0.05888"/>
    <parent link="arm_seg4"/>
    <child link="arm_seg5"/>
    <axis xyz="0 0 1"/>
    <limit effort="100" lower="-2.61666" upper="2.61666" velocity="1"/>
  </joint>
  <link name="arm_seg6">
    <inertial>
      <origin rpy="0 0 0" xyz="-0.00040425 0.0066328 -0.012475"/>
      <mass value="0.27794"/>
      <inertia ixx="0.00024751" ixy="-5.6849E-09" ixz="5.4838E-10" iyy="0.00017648" iyz="-2.8552E-05" izz="0.00019295"/>
    </inertial>
    <visual>
      <origin rpy="0 0 0" xyz="0 0 0"/>
      <geometry>
        <mesh filename="package://x1_dvt_description/meshes/arm_seg6.STL"/>
      </geometry>
      <material name="">
        <color rgba="0.29804 0.28627 0.28235 1"/>
      </material>
    </visual>
    <collision>
      <origin rpy="0 0 0" xyz="0 0.0 -0.02"/>
      <geometry>
        <cylinder length="0.06" radius="0.03"/>
      </geometry>
    </collision>
    <collision>
      <origin rpy="1.570796 0 0" xyz="0 0.005 0.0"/>
      <geometry>
        <cylinder length="0.094" radius="0.032"/>
      </geometry>
    </collision>
  </link>
  <joint name="seg5_to_seg6" type="revolute">
    <origin rpy="1.5708 0 0" xyz="0.00040486 -0.10983 0"/>
    <parent link="arm_seg5"/>
    <child link="arm_seg6"/>
    <axis xyz="0 0 1"/>
    <limit effort="100" lower="-2.96555" upper="2.96555" velocity="1"/>
  </joint>
  <link name="arm_seg7">
    <inertial>
      <origin rpy="0 0 0" xyz="0.00095587 -0.0013555 -0.010297"/>
      <mass value="0.033025"/>
      <inertia ixx="1.2968E-05" ixy="-7.8692E-07" ixz="8.451E-08" iyy="1.1583E-05" iyz="-1.2002E-07" izz="2.0405E-05"/>
    </inertial>
    <visual>
      <origin rpy="0 0 0" xyz="0 0 0"/>
      <geometry>
        <mesh filename="package://x1_dvt_description/meshes/arm_seg7.STL"/>
      </geometry>
      <material name="">
        <color rgba="1 1 0.9451 1"/>
      </material>
    </visual>
    <collision>
      <origin rpy="0 0 0" xyz="0 0 -0.01"/>
      <geometry>
        <cylinder length="0.04" radius="0.04"/>
      </geometry>
    </collision>
    <collision>
      <origin rpy="1.5707 0 1.0472" xyz="0.038 -0.025 -0.012"/>
      <geometry>
        <cylinder length="0.02" radius="0.005"/>
      </geometry>
    </collision>
  </link>
  <joint name="seg6_to_seg7" type="revolute">
    <origin rpy="-1.5708 0 0" xyz="0 0.0795 0"/>
    <parent link="arm_seg6"/>
    <child link="arm_seg7"/>
    <axis xyz="0 0 1"/>
    <limit effort="100" lower="-2.96555" upper="2.96555" velocity="1"/>
  </joint>
  <link name="gripper_body">
    <inertial>
      <origin rpy="0 0 0" xyz="0.000390707060136775 -0.0540735193776723 0.000138638255571477"/>
      <mass value="0.298157694389122"/>
      <inertia ixx="0.000373449293126774" ixy="2.12064813494508E-06" ixz="1.54746655528999E-09" iyy="0.000138130088316942" iyz="2.35024712014999E-06" izz="0.000380963420969193"/>
    </inertial>
    <visual>
      <origin rpy="0 0 0" xyz="0 0 0"/>
      <geometry>
        <mesh filename="package://x1_dvt_description/meshes/gripper_body.STL"/>
      </geometry>
      <material name="">
        <color rgba="0.866666666666667 0.854901960784314 0.788235294117647 1"/>
      </material>
    </visual>
    <collision>
      <origin rpy="-1.570796 0 0" xyz="0 -0.07 0"/>
      <geometry>
        <box size="0.065 0.045 0.14"/>
      </geometry>
    </collision>
    <collision>
      <origin rpy="-1.570796 0 0" xyz="0.0 -0.05 -0.0575"/>
      <geometry>
        <box size="0.09 0.07 0.03"/>
      </geometry>
    </collision>
  </link>
  <joint name="gripper_body_fixed" type="fixed">
    <origin rpy="-1.570796 0 0" xyz="0 0 0.0075"/>
    <parent link="arm_seg7"/>
    <child link="gripper_body"/>
  </joint>
  <link name="eef"/>
  <joint name="eef_fixed_joint" type="fixed">
    <origin rpy="0 3.141592653589793 1.5707963267948966" xyz="0 -0.25 0"/>
    <parent link="gripper_body"/>
    <child link="eef"/>
  </joint>
  <link name="finger1">
    <inertial>
      <origin rpy="0 0 0" xyz="0.00389084053875241 -0.0439347025463299 0.0125073717596533"/>
      <mass value="0.0230695125753105"/>
      <inertia ixx="1.08857965605712E-05" ixy="-1.60798649937533E-07" ixz="-2.19630042897636E-08" iyy="1.62872616449687E-06" iyz="-5.70263553510615E-08" izz="1.01780418076526E-05"/>
    </inertial>
    <visual>
      <origin rpy="0 0 0" xyz="0 0 0"/>
      <geometry>
        <mesh filename="package://x1_dvt_description/meshes/finger1.STL"/>
      </geometry>
      <material name="">
        <color rgba="0.866666666666667 0.854901960784314 0.788235294117647 1"/>
      </material>
    </visual>
    <collision>
      <origin rpy="0 0 0" xyz="0.0035 -0.068 0.0125"/>
      <geometry>
        <box size="0.02 0.09 0.025"/>
      </geometry>
    </collision>
  </link>
  <joint name="finger1_joint" type="revolute">
    <origin rpy="0 0 0" xyz="-0.02 -0.11703 -0.0122"/>
    <parent link="gripper_body"/>
    <child link="finger1"/>
    <axis xyz="0 0 -1"/>
    <limit effort="10" lower="0" upper="0.785" velocity="1"/>
  </joint>
  <link name="finger2">
    <inertial>
      <origin rpy="0 0 0" xyz="-0.00448714312864135 -0.0439461801413309 0.0122926314150753"/>
      <mass value="0.023069513141593"/>
      <inertia ixx="1.09023595171387E-05" ixy="2.17805310482506E-08" ixz="-2.09818375387175E-08" iyy="1.61216389214684E-06" iyz="5.73924519733115E-08" izz="1.01780419210114E-05"/>
    </inertial>
    <visual>
      <origin rpy="0 0 0" xyz="0 0 0"/>
      <geometry>
        <mesh filename="package://x1_dvt_description/meshes/finger2.STL"/>
      </geometry>
      <material name="">
        <color rgba="0.866666666666667 0.854901960784314 0.788235294117647 1"/>
      </material>
    </visual>
    <collision>
      <origin rpy="0 0 0" xyz="-0.0035 -0.068 0.0125"/>
      <geometry>
        <box size="0.02 0.09 0.025"/>
      </geometry>
    </collision>
  </link>
  <joint name="finger2_joint" type="revolute">
    <origin rpy="0 0 0" xyz="0.02 -0.11703 -0.0122"/>
    <parent link="gripper_body"/>
    <child link="finger2"/>
    <axis xyz="0 0 1"/>
    <limit effort="10" lower="0" upper="0.785" velocity="1"/>
  </joint>
</robot>
